<?xml version="1.0" encoding="UTF-8"?><testrun name="src (1)" project="VendingMachine" tests="10" started="10" failures="0" errors="1" ignored="0">
  <testsuite name="edu.towson.cis.cosc442.project2.vendingmachine.VendingMachineTest" time="0.0">
    <testcase name="testAddItem" classname="edu.towson.cis.cosc442.project2.vendingmachine.VendingMachineTest" time="0.0"/>
    <testcase name="testInsertMoney" classname="edu.towson.cis.cosc442.project2.vendingmachine.VendingMachineTest" time="0.0"/>
    <testcase name="testGetItem" classname="edu.towson.cis.cosc442.project2.vendingmachine.VendingMachineTest" time="0.0"/>
    <testcase name="testMakePurchase" classname="edu.towson.cis.cosc442.project2.vendingmachine.VendingMachineTest" time="0.0"/>
    <testcase name="testGetBalance" classname="edu.towson.cis.cosc442.project2.vendingmachine.VendingMachineTest" time="0.0"/>
    <testcase name="testRemoveItem" classname="edu.towson.cis.cosc442.project2.vendingmachine.VendingMachineTest" time="0.0"/>
    <testcase name="testReturnChange" classname="edu.towson.cis.cosc442.project2.vendingmachine.VendingMachineTest" time="0.0"/>
  </testsuite>
  <testsuite name="edu.towson.cis.cosc442.project2.vendingmachine.VendingMachineItemTest" time="0.0">
    <testcase name="VendingMachineException" classname="edu.towson.cis.cosc442.project2.vendingmachine.VendingMachineItemTest" time="0.001">
      <error>java.lang.Exception: Unexpected exception, expected&lt;edu.towson.cis.cosc442.project2.vendingmachine.VendingMachineException&gt; but was&lt;java.lang.AssertionError&gt;&#13;
	at org.junit.internal.runners.statements.ExpectException.evaluate(ExpectException.java:28)&#13;
	at org.junit.internal.runners.statements.RunBefores.evaluate(RunBefores.java:26)&#13;
	at org.junit.internal.runners.statements.RunAfters.evaluate(RunAfters.java:27)&#13;
	at org.junit.runners.ParentRunner.runLeaf(ParentRunner.java:325)&#13;
	at org.junit.runners.BlockJUnit4ClassRunner.runChild(BlockJUnit4ClassRunner.java:78)&#13;
	at org.junit.runners.BlockJUnit4ClassRunner.runChild(BlockJUnit4ClassRunner.java:57)&#13;
	at org.junit.runners.ParentRunner$3.run(ParentRunner.java:290)&#13;
	at org.junit.runners.ParentRunner$1.schedule(ParentRunner.java:71)&#13;
	at org.junit.runners.ParentRunner.runChildren(ParentRunner.java:288)&#13;
	at org.junit.runners.ParentRunner.access$000(ParentRunner.java:58)&#13;
	at org.junit.runners.ParentRunner$2.evaluate(ParentRunner.java:268)&#13;
	at org.junit.runners.ParentRunner.run(ParentRunner.java:363)&#13;
	at org.eclipse.jdt.internal.junit4.runner.JUnit4TestReference.run(JUnit4TestReference.java:50)&#13;
	at org.eclipse.jdt.internal.junit.runner.TestExecution.run(TestExecution.java:38)&#13;
	at org.eclipse.jdt.internal.junit.runner.RemoteTestRunner.runTests(RemoteTestRunner.java:459)&#13;
	at org.eclipse.jdt.internal.junit.runner.RemoteTestRunner.runTests(RemoteTestRunner.java:675)&#13;
	at org.eclipse.jdt.internal.junit.runner.RemoteTestRunner.run(RemoteTestRunner.java:382)&#13;
	at org.eclipse.jdt.internal.junit.runner.RemoteTestRunner.main(RemoteTestRunner.java:192)&#13;
Caused by: java.lang.AssertionError&#13;
	at org.junit.Assert.fail(Assert.java:86)&#13;
	at org.junit.Assert.assertTrue(Assert.java:41)&#13;
	at org.junit.Assert.assertTrue(Assert.java:52)&#13;
	at edu.towson.cis.cosc442.project2.vendingmachine.VendingMachineItemTest.VendingMachineException(VendingMachineItemTest.java:50)&#13;
	at sun.reflect.NativeMethodAccessorImpl.invoke0(Native Method)&#13;
	at sun.reflect.NativeMethodAccessorImpl.invoke(Unknown Source)&#13;
	at sun.reflect.DelegatingMethodAccessorImpl.invoke(Unknown Source)&#13;
	at java.lang.reflect.Method.invoke(Unknown Source)&#13;
	at org.junit.runners.model.FrameworkMethod$1.runReflectiveCall(FrameworkMethod.java:50)&#13;
	at org.junit.internal.runners.model.ReflectiveCallable.run(ReflectiveCallable.java:12)&#13;
	at org.junit.runners.model.FrameworkMethod.invokeExplosively(FrameworkMethod.java:47)&#13;
	at org.junit.internal.runners.statements.InvokeMethod.evaluate(InvokeMethod.java:17)&#13;
	at org.junit.internal.runners.statements.ExpectException.evaluate(ExpectException.java:19)&#13;
	... 17 more&#13;
&#13;
</error>
    </testcase>
    <testcase name="testGetName" classname="edu.towson.cis.cosc442.project2.vendingmachine.VendingMachineItemTest" time="0.0"/>
    <testcase name="testGetPrice1" classname="edu.towson.cis.cosc442.project2.vendingmachine.VendingMachineItemTest" time="0.0"/>
  </testsuite>
</testrun>
